Workbook
Name NativeTimeline_OrderDate: #N/A
Name Slicer_Category: #N/A
Name Slicer_months: #N/A
Name Slicer_Region: #N/A
Name SUM_OF_SALSE: Sheet2!$I$20:$J$27
Name sum_of_the_salse: Sheet2!$I$22

Sheet Order Table
A1: OrderID | B1: CustomerID | C1: ProductID | D1: Quantity | E1: OrderDate | F1: Profit
A2: 1001 | B2: C001 | C2: P001 | D2: 2 | E2: 45293 | F2: 1800
A3: 1002 | B3: C002 | C3: P006 | D3: 1 | E3: 45294 | F3: 700
A4: 1003 | B4: C003 | C4: P005 | D4: 1 | E4: 45295 | F4: 1500
A5: 1004 | B5: C004 | C5: P009 | D5: 1 | E5: 45296 | F5: 300
A6: 1005 | B6: C005 | C6: P003 | D6: 3 | E6: 45297 | F6: 18000
A7: 1006 | B7: C006 | C7: P004 | D7: 4 | E7: 45297 | F7: 1600
A8: 1007 | B8: C007 | C8: P011 | D8: 1 | E8: 45298 | F8: 900
A9: 1008 | B9: C008 | C9: P002 | D9: 2 | E9: 45298 | F9: 700
A10: 1009 | B10: C009 | C10: P003 | D10: 1 | E10: 45299 | F10: 12000
A11: 1010 | B11: C010 | C11: P007 | D11: 1 | E11: 45299 | F11: 300
A12: 1011 | B12: C011 | C12: P014 | D12: 1 | E12: 45300 | F12: 1800
A13: 1012 | B13: C012 | C13: P003 | D13: 2 | E13: 45301 | F13: 900
... A80: 1079 | B80: C040 | C80: P007 | D80: 2 | E80: 45359 | F80: 2000

Sheet Product_table
A1: ProductID | B1: ProductName | C1: Category | D1: Price
A2: P001 | B2: Amazon Echo Dot | C2: Electronics | D2: 4500
A3: P002 | B3: Fire TV Stick | C3: Electronics | D3: 2999
A4: P003 | B4: Noise Headphones | C4: Accessories | D4: 1999
A5: P004 | B5: Mobile Back Cover | C5: Accessories | D5: 299
A6: P005 | B6: Apple MacBook Air | C6: Electronics | D6: 92000
A7: P006 | B7: Boat Speakers | C7: Electronics | D7: 3500
A8: P007 | B8: Comfort Chair | C8: Furniture | D8: 5500
A9: P008 | B9: Laptop Stand | C9: Accessories | D9: 899
A10: P009 | B10: HP Laptop 15 | C10: Electronics | D10: 58000
A11: P010 | B11: USB Cable | C11: Accessories | D11: 249
A12: P011 | B12: Smartwatch Pro | C12: Electronics | D12: 4500
A13: P012 | B13: Wireless Mouse | C13: Accessories | D13: 799
... A31: P030 | B31: Water Bottle | C31: Home | D31: 399

Sheet Customer
A1: CustomerID | B1: CustomerName | C1: Region
A2: C001 | B2: Rohit Sharma | C2: North
A3: C002 | B3: Neha Verma | C3: South
A4: C003 | B4: Aman Gupta | C4: West
A5: C004 | B5: Pooja Patil | C5: East
A6: C005 | B6: Ali Khan | C6: North
A7: C006 | B7: Sonali Desai | C7: South
A8: C007 | B8: Manish Jain | C8: West
A9: C008 | B9: Asha Singh | C9: East
A10: C009 | B10: Varun Mehta | C10: North
A11: C010 | B11: Deepa Reddy | C11: South
A12: C011 | B12: Riya Kapoor | C12: West
... A41: C040 | B41: Siddharth Jain | C41: East

Sheet project
A1: OrderID | B1: CustomerID | C1: ProductID | D1: Quantity | E1: OrderDate | F1: Profit | G1: CustomerName | H1: Region | I1: ProductName | J1: Category | K1: Price | L1: Salse | M1: profit Margin | N1: year | O1: month | P1: months | Q1: months
A2: 1001 | B2: C001 | C2: P001 | D2: 2 | E2: 45293 | F2: 1800 | G2: =VLOOKUP(project!$B2,Customer!$A$1:$C$41,MATCH(Customer!B$1,Customer!$A$1:$C$1,0),FALSE) -> Rohit Sharma | H2: =VLOOKUP(project!$B2,Customer!$A$1:$C$41,MATCH(Customer!C$1,Customer!$A$1:$C$1,0),FALSE) -> North | I2: =VLOOKUP(project!$C2,Product_table!$A$1:$D$31,MATCH(Product_table!B$1,Product_table!$A$1:$D$1,0)) -> Amazon Echo Dot | J2: =VLOOKUP(project!$C2,Product_table!$A$1:$D$31,MATCH(Product_table!C$1,Product_table!$A$1:$D$1,0)) -> Electronics | K2: =VLOOKUP(project!$C2,Product_table!$A$1:$D$31,MATCH(Product_table!D$1,Product_table!$A$1:$D$1,0)) -> 4500 | L2: =Table2[[#This Row],[Price]]*Table2[[#This Row],[Quantity]] -> 9000 | M2: =Table2[[#This Row],[Profit]]/Table2[[#This Row],[Salse]] -> 0.2 | N2: =YEAR(Table2[[#This Row],[OrderDate]]) -> 2024 | O2: =MONTH(Table2[[#This Row],[OrderDate]]) -> 1 | P2: =TEXT(Table2[[#This Row],[OrderDate]],"mmm") -> Jan
A3: 1002 | B3: C002 | C3: P006 | D3: 1 | E3: 45294 | F3: 700 | G3: =VLOOKUP(project!$B3,Customer!$A$1:$C$41,MATCH(Customer!B$1,Customer!$A$1:$C$1,0),FALSE) -> Neha Verma | H3: =VLOOKUP(project!$B3,Customer!$A$1:$C$41,MATCH(Customer!C$1,Customer!$A$1:$C$1,0),FALSE) -> South | I3: =VLOOKUP(project!$C3,Product_table!$A$1:$D$31,MATCH(Product_table!B$1,Product_table!$A$1:$D$1,0)) -> Boat Speakers | J3: =VLOOKUP(project!$C3,Product_table!$A$1:$D$31,MATCH(Product_table!C$1,Product_table!$A$1:$D$1,0)) -> Electronics | K3: =VLOOKUP(project!$C3,Product_table!$A$1:$D$31,MATCH(Product_table!D$1,Product_table!$A$1:$D$1,0)) -> 3500 | L3: =Table2[[#This Row],[Price]]*Table2[[#This Row],[Quantity]] -> 3500 | M3: =Table2[[#This Row],[Profit]]/Table2[[#This Row],[Salse]] -> 0.2 | N3: =YEAR(Table2[[#This Row],[OrderDate]]) -> 2024 | O3: =MONTH(Table2[[#This Row],[OrderDate]]) -> 1 | P3: =TEXT(Table2[[#This Row],[OrderDate]],"mmm") -> Jan
A4: 1003 | B4: C003 | C4: P005 | D4: 1 | E4: 45295 | F4: 1500 | G4: =VLOOKUP(project!$B4,Customer!$A$1:$C$41,MATCH(Customer!B$1,Customer!$A$1:$C$1,0),FALSE) -> Aman Gupta | H4: =VLOOKUP(project!$B4,Customer!$A$1:$C$41,MATCH(Customer!C$1,Customer!$A$1:$C$1,0),FALSE) -> West | I4: =VLOOKUP(project!$C4,Product_table!$A$1:$D$31,MATCH(Product_table!B$1,Product_table!$A$1:$D$1,0)) -> Apple MacBook Air | J4: =VLOOKUP(project!$C4,Product_table!$A$1:$D$31,MATCH(Product_table!C$1,Product_table!$A$1:$D$1,0)) -> Electronics | K4: =VLOOKUP(project!$C4,Product_table!$A$1:$D$31,MATCH(Product_table!D$1,Product_table!$A$1:$D$1,0)) -> 92000 | L4: =Table2[[#This Row],[Price]]*Table2[[#This Row],[Quantity]] -> 92000 | M4: =Table2[[#This Row],[Profit]]/Table2[[#This Row],[Salse]] -> 0.016304348 | N4: =YEAR(Table2[[#This Row],[OrderDate]]) -> 2024 | O4: =MONTH(Table2[[#This Row],[OrderDate]]) -> 1 | P4: =TEXT(Table2[[#This Row],[OrderDate]],"mmm") -> Jan
A5: 1004 | B5: C004 | C5: P009 | D5: 1 | E5: 45296 | F5: 300 | G5: =VLOOKUP(project!$B5,Customer!$A$1:$C$41,MATCH(Customer!B$1,Customer!$A$1:$C$1,0),FALSE) -> Pooja Patil | H5: =VLOOKUP(project!$B5,Customer!$A$1:$C$41,MATCH(Customer!C$1,Customer!$A$1:$C$1,0),FALSE) -> East | I5: =VLOOKUP(project!$C5,Product_table!$A$1:$D$31,MATCH(Product_table!B$1,Product_table!$A$1:$D$1,0)) -> HP Laptop 15 | J5: =VLOOKUP(project!$C5,Product_table!$A$1:$D$31,MATCH(Product_table!C$1,Product_table!$A$1:$D$1,0)) -> Electronics | K5: =VLOOKUP(project!$C5,Product_table!$A$1:$D$31,MATCH(Product_table!D$1,Product_table!$A$1:$D$1,0)) -> 58000 | L5: =Table2[[#This Row],[Price]]*Table2[[#This Row],[Quantity]] -> 58000 | M5: =Table2[[#This Row],[Profit]]/Table2[[#This Row],[Salse]] -> 0.0051724138 | N5: =YEAR(Table2[[#This Row],[OrderDate]]) -> 2024 | O5: =MONTH(Table2[[#This Row],[OrderDate]]) -> 1 | P5: =TEXT(Table2[[#This Row],[OrderDate]],"mmm") -> Jan
A6: 1005 | B6: C005 | C6: P003 | D6: 3 | E6: 45297 | F6: 18000 | G6: =VLOOKUP(project!$B6,Customer!$A$1:$C$41,MATCH(Customer!B$1,Customer!$A$1:$C$1,0),FALSE) -> Ali Khan | H6: =VLOOKUP(project!$B6,Customer!$A$1:$C$41,MATCH(Customer!C$1,Customer!$A$1:$C$1,0),FALSE) -> North | I6: =VLOOKUP(project!$C6,Product_table!$A$1:$D$31,MATCH(Product_table!B$1,Product_table!$A$1:$D$1,0)) -> Noise Headphones | J6: =VLOOKUP(project!$C6,Product_table!$A$1:$D$31,MATCH(Product_table!C$1,Product_table!$A$1:$D$1,0)) -> Accessories | K6: =VLOOKUP(project!$C6,Product_table!$A$1:$D$31,MATCH(Product_table!D$1,Product_table!$A$1:$D$1,0)) -> 1999 | L6: =Table2[[#This Row],[Price]]*Table2[[#This Row],[Quantity]] -> 5997 | M6: =Table2[[#This Row],[Profit]]/Table2[[#This Row],[Salse]] -> 3.0015008 | N6: =YEAR(Table2[[#This Row],[OrderDate]]) -> 2024 | O6: =MONTH(Table2[[#This Row],[OrderDate]]) -> 1 | P6: =TEXT(Table2[[#This Row],[OrderDate]],"mmm") -> Jan
A7: 1006 | B7: C006 | C7: P004 | D7: 4 | E7: 45297 | F7: 1600 | G7: =VLOOKUP(project!$B7,Customer!$A$1:$C$41,MATCH(Customer!B$1,Customer!$A$1:$C$1,0),FALSE) -> Sonali Desai | H7: =VLOOKUP(project!$B7,Customer!$A$1:$C$41,MATCH(Customer!C$1,Customer!$A$1:$C$1,0),FALSE) -> South | I7: =VLOOKUP(project!$C7,Product_table!$A$1:$D$31,MATCH(Product_table!B$1,Product_table!$A$1:$D$1,0)) -> Mobile Back Cover | J7: =VLOOKUP(project!$C7,Product_table!$A$1:$D$31,MATCH(Product_table!C$1,Product_table!$A$1:$D$1,0)) -> Accessories | K7: =VLOOKUP(project!$C7,Product_table!$A$1:$D$31,MATCH(Product_table!D$1,Product_table!$A$1:$D$1,0)) -> 299 | L7: =Table2[[#This Row],[Price]]*Table2[[#This Row],[Quantity]] -> 1196 | M7: =Table2[[#This Row],[Profit]]/Table2[[#This Row],[Salse]] -> 1.3377926 | N7: =YEAR(Table2[[#This Row],[OrderDate]]) -> 2024 | O7: =MONTH(Table2[[#This Row],[OrderDate]]) -> 1 | P7: =TEXT(Table2[[#This Row],[OrderDate]],"mmm") -> Jan
A8: 1007 | B8: C007 | C8: P011 | D8: 1 | E8: 45298 | F8: 900 | G8: =VLOOKUP(project!$B8,Customer!$A$1:$C$41,MATCH(Customer!B$1,Customer!$A$1:$C$1,0),FALSE) -> Manish Jain | H8: =VLOOKUP(project!$B8,Customer!$A$1:$C$41,MATCH(Customer!C$1,Customer!$A$1:$C$1,0),FALSE) -> West | I8: =VLOOKUP(project!$C8,Product_table!$A$1:$D$31,MATCH(Product_table!B$1,Product_table!$A$1:$D$1,0)) -> Smartwatch Pro | J8: =VLOOKUP(project!$C8,Product_table!$A$1:$D$31,MATCH(Product_table!C$1,Product_table!$A$1:$D$1,0)) -> Electronics | K8: =VLOOKUP(project!$C8,Product_table!$A$1:$D$31,MATCH(Product_table!D$1,Product_table!$A$1:$D$1,0)) -> 4500 | L8: =Table2[[#This Row],[Price]]*Table2[[#This Row],[Quantity]] -> 4500 | M8: =Table2[[#This Row],[Profit]]/Table2[[#This Row],[Salse]] -> 0.2 | N8: =YEAR(Table2[[#This Row],[OrderDate]]) -> 2024 | O8: =MONTH(Table2[[#This Row],[OrderDate]]) -> 1 | P8: =TEXT(Table2[[#This Row],[OrderDate]],"mmm") -> Jan
A9: 1008 | B9: C008 | C9: P002 | D9: 2 | E9: 45298 | F9: 700 | G9: =VLOOKUP(project!$B9,Customer!$A$1:$C$41,MATCH(Customer!B$1,Customer!$A$1:$C$1,0),FALSE) -> Asha Singh | H9: =VLOOKUP(project!$B9,Customer!$A$1:$C$41,MATCH(Customer!C$1,Customer!$A$1:$C$1,0),FALSE) -> East | I9: =VLOOKUP(project!$C9,Product_table!$A$1:$D$31,MATCH(Product_table!B$1,Product_table!$A$1:$D$1,0)) -> Fire TV Stick | J9: =VLOOKUP(project!$C9,Product_table!$A$1:$D$31,MATCH(Product_table!C$1,Product_table!$A$1:$D$1,0)) -> Electronics | K9: =VLOOKUP(project!$C9,Product_table!$A$1:$D$31,MATCH(Product_table!D$1,Product_table!$A$1:$D$1,0)) -> 2999 | L9: =Table2[[#This Row],[Price]]*Table2[[#This Row],[Quantity]] -> 5998 | M9: =Table2[[#This Row],[Profit]]/Table2[[#This Row],[Salse]] -> 0.11670557 | N9: =YEAR(Table2[[#This Row],[OrderDate]]) -> 2024 | O9: =MONTH(Table2[[#This Row],[OrderDate]]) -> 1 | P9: =TEXT(Table2[[#This Row],[OrderDate]],"mmm") -> Jan
A10: 1009 | B10: C009 | C10: P003 | D10: 1 | E10: 45299 | F10: 12000 | G10: =VLOOKUP(project!$B10,Customer!$A$1:$C$41,MATCH(Customer!B$1,Customer!$A$1:$C$1,0),FALSE) -> Varun Mehta | H10: =VLOOKUP(project!$B10,Customer!$A$1:$C$41,MATCH(Customer!C$1,Customer!$A$1:$C$1,0),FALSE) -> North | I10: =VLOOKUP(project!$C10,Product_table!$A$1:$D$31,MATCH(Product_table!B$1,Product_table!$A$1:$D$1,0)) -> Noise Headphones | J10: =VLOOKUP(project!$C10,Product_table!$A$1:$D$31,MATCH(Product_table!C$1,Product_table!$A$1:$D$1,0)) -> Accessories | K10: =VLOOKUP(project!$C10,Product_table!$A$1:$D$31,MATCH(Product_table!D$1,Product_table!$A$1:$D$1,0)) -> 1999 | L10: =Table2[[#This Row],[Price]]*Table2[[#This Row],[Quantity]] -> 1999 | M10: =Table2[[#This Row],[Profit]]/Table2[[#This Row],[Salse]] -> 6.0030015 | N10: =YEAR(Table2[[#This Row],[OrderDate]]) -> 2024 | O10: =MONTH(Table2[[#This Row],[OrderDate]]) -> 1 | P10: =TEXT(Table2[[#This Row],[OrderDate]],"mmm") -> Jan
A11: 1010 | B11: C010 | C11: P007 | D11: 1 | E11: 45299 | F11: 300 | G11: =VLOOKUP(project!$B11,Customer!$A$1:$C$41,MATCH(Customer!B$1,Customer!$A$1:$C$1,0),FALSE) -> Deepa Reddy | H11: =VLOOKUP(project!$B11,Customer!$A$1:$C$41,MATCH(Customer!C$1,Customer!$A$1:$C$1,0),FALSE) -> South | I11: =VLOOKUP(project!$C11,Product_table!$A$1:$D$31,MATCH(Product_table!B$1,Product_table!$A$1:$D$1,0)) -> Comfort Chair | J11: =VLOOKUP(project!$C11,Product_table!$A$1:$D$31,MATCH(Product_table!C$1,Product_table!$A$1:$D$1,0)) -> Furniture | K11: =VLOOKUP(project!$C11,Product_table!$A$1:$D$31,MATCH(Product_table!D$1,Product_table!$A$1:$D$1,0)) -> 5500 | L11: =Table2[[#This Row],[Price]]*Table2[[#This Row],[Quantity]] -> 5500 | M11: =Table2[[#This Row],[Profit]]/Table2[[#This Row],[Salse]] -> 0.054545455 | N11: =YEAR(Table2[[#This Row],[OrderDate]]) -> 2024 | O11: =MONTH(Table2[[#This Row],[OrderDate]]) -> 1 | P11: =TEXT(Table2[[#This Row],[OrderDate]],"mmm") -> Jan
A12: 1011 | B12: C011 | C12: P014 | D12: 1 | E12: 45300 | F12: 1800 | G12: =VLOOKUP(project!$B12,Customer!$A$1:$C$41,MATCH(Customer!B$1,Customer!$A$1:$C$1,0),FALSE) -> Riya Kapoor | H12: =VLOOKUP(project!$B12,Customer!$A$1:$C$41,MATCH(Customer!C$1,Customer!$A$1:$C$1,0),FALSE) -> West | I12: =VLOOKUP(project!$C12,Product_table!$A$1:$D$31,MATCH(Product_table!B$1,Product_table!$A$1:$D$1,0)) -> Office Desk | J12: =VLOOKUP(project!$C12,Product_table!$A$1:$D$31,MATCH(Product_table!C$1,Product_table!$A$1:$D$1,0)) -> Furniture | K12: =VLOOKUP(project!$C12,Product_table!$A$1:$D$31,MATCH(Product_table!D$1,Product_table!$A$1:$D$1,0)) -> 8500 | L12: =Table2[[#This Row],[Price]]*Table2[[#This Row],[Quantity]] -> 8500 | M12: =Table2[[#This Row],[Profit]]/Table2[[#This Row],[Salse]] -> 0.21176471 | N12: =YEAR(Table2[[#This Row],[OrderDate]]) -> 2024 | O12: =MONTH(Table2[[#This Row],[OrderDate]]) -> 1 | P12: =TEXT(Table2[[#This Row],[OrderDate]],"mmm") -> Jan
A13: 1012 | B13: C012 | C13: P003 | D13: 2 | E13: 45301 | F13: 900 | G13: =VLOOKUP(project!$B13,Customer!$A$1:$C$41,MATCH(Customer!B$1,Customer!$A$1:$C$1,0),FALSE) -> Rajat Singh | H13: =VLOOKUP(project!$B13,Customer!$A$1:$C$41,MATCH(Customer!C$1,Customer!$A$1:$C$1,0),FALSE) -> East | I13: =VLOOKUP(project!$C13,Product_table!$A$1:$D$31,MATCH(Product_table!B$1,Product_table!$A$1:$D$1,0)) -> Noise Headphones | J13: =VLOOKUP(project!$C13,Product_table!$A$1:$D$31,MATCH(Product_table!C$1,Product_table!$A$1:$D$1,0)) -> Accessories | K13: =VLOOKUP(project!$C13,Product_table!$A$1:$D$31,MATCH(Product_table!D$1,Product_table!$A$1:$D$1,0)) -> 1999 | L13: =Table2[[#This Row],[Price]]*Table2[[#This Row],[Quantity]] -> 3998 | M13: =Table2[[#This Row],[Profit]]/Table2[[#This Row],[Salse]] -> 0.22511256 | N13: =YEAR(Table2[[#This Row],[OrderDate]]) -> 2024 | O13: =MONTH(Table2[[#This Row],[OrderDate]]) -> 1 | P13: =TEXT(Table2[[#This Row],[OrderDate]],"mmm") -> Jan
... A80: 1079 | B80: C040 | C80: P007 | D80: 2 | E80: 45359 | F80: 2000 | G80: =VLOOKUP(project!$B80,Customer!$A$1:$C$41,MATCH(Customer!B$1,Customer!$A$1:$C$1,0),FALSE) -> Siddharth Jain | H80: =VLOOKUP(project!$B80,Customer!$A$1:$C$41,MATCH(Customer!C$1,Customer!$A$1:$C$1,0),FALSE) -> East | I80: =VLOOKUP(project!$C80,Product_table!$A$1:$D$31,MATCH(Product_table!B$1,Product_table!$A$1:$D$1,0)) -> Comfort Chair | J80: =VLOOKUP(project!$C80,Product_table!$A$1:$D$31,MATCH(Product_table!C$1,Product_table!$A$1:$D$1,0)) -> Furniture | K80: =VLOOKUP(project!$C80,Product_table!$A$1:$D$31,MATCH(Product_table!D$1,Product_table!$A$1:$D$1,0)) -> 5500 | L80: =Table2[[#This Row],[Price]]*Table2[[#This Row],[Quantity]] -> 11000 | M80: =Table2[[#This Row],[Profit]]/Table2[[#This Row],[Salse]] -> 0.18181818 | N80: =YEAR(Table2[[#This Row],[OrderDate]]) -> 2024 | O80: =MONTH(Table2[[#This Row],[OrderDate]]) -> 3 | P80: =TEXT(Table2[[#This Row],[OrderDate]],"mmm") -> Mar

Sheet Sheet2
A1: Row Labels | B1: Sum of Salse | E1: Row Labels | F1: Sum of Salse | I1: Row Labels | J1: Sum of Salse
A2: East | B2: 182875 | E2: Accessories | F2: 75128 | I2: Jan | J2: 413003
A3: North | B3: 127775 | E3: Electronics | F3: 601685 | I3: Feb | J3: 220913
A4: South | B4: 139676 | E4: FMCG | F4: 1800 | I4: Mar | J4: 98295
A5: West | B5: 281885 | E5: Furniture | F5: 53000 | I5: Grand Total | J5: 732211
A6: Grand Total | B6: 732211 | E6: Stationery | F6: 598
E7: Grand Total | F7: 732211
A10: Row Labels | B10: Sum of Profit | E10: Row Labels | F10: Sum of Profit | I10: Row Labels | J10: Sum of Profit
A11: East | B11: 36300 | E11: East | I11: Jan | J11: 104230
A12: North | B12: 100750 | E12: Accessories | F12: 8250 | I12: Feb | J12: 73750
A13: South | B13: 44350 | E13: Electronics | F13: 25200 | I13: Mar | J13: 25350
A14: West | B14: 21930 | E14: Furniture | F14: 2000 | I14: Grand Total | J14: 203330
A15: Grand Total | B15: 203330 | E15: Stationery | F15: 850
E16: North
E17: Accessories | F17: 89950
E18: Electronics | F18: 9500
A19: Row Labels | B19: Sum of Profit | C19: Sum of Salse | E19: Furniture | F19: 1300
A20: Amazon Echo Dot | B20: 34100 | C20: 36000 | E20: South | I20: sum of the salse
A21: Apple MacBook Air | B21: 1500 | C21: 92000 | E21: Accessories | F21: 21250
A22: Backpack | B22: 16400 | C22: 3897 | E22: Electronics | F22: 21900 | I22: =SUM(project!L2:L80) -> 732211
A23: Boat Speakers | B23: 4380 | C23: 28000 | E23: FMCG | F23: 900
A24: Comfort Chair | B24: 4200 | C24: 27500 | E24: Furniture | F24: 300
A25: Extension Board | B25: 1250 | C25: 3495 | E25: West
A26: Fire TV Stick | B26: 2900 | C26: 14995 | E26: Accessories | F26: 6050
A27: Gaming Mouse | B27: 5800 | C27: 9995 | E27: Electronics | F27: 11180
A28: HP Laptop 15 | B28: 4800 | C28: 348000 | E28: Furniture | F28: 4700
A29: Laptop Stand | B29: 850 | C29: 4495
A30: LED Monitor | B30: 1250 | C30: 25000 | I30: =sum_of_the_salse -> 732211
A31: Mobile Back Cover | B31: 6000 | C31: 3887
A32: Noise Headphones | B32: 81200 | C32: 47976
A33: Notebook Set | B33: 850 | C33: 598 | E33: Row Labels | F33: Sum of Profit
A34: Office Desk | B34: 4100 | C34: 25500 | E34: East
A35: Pen Drive 64GB | B35: 2900 | C35: 2397 | E35: Accessories | F35: 8250
A36: Portable SSD 1TB | B36: 900 | C36: 9500 | E36: Electronics | F36: 25200
A37: Printer Ink | B37: 900 | C37: 1800 | E37: Furniture | F37: 2000
A38: Smart Bulb | B38: 2900 | C38: 1798 | E38: Stationery | F38: 850
A39: Smartwatch Pro | B39: 5550 | C39: 31500 | E39: North
A40: Tripod Stand | B40: 13500 | C40: 2994 | E40: Accessories | F40: 89950
A41: USB Cable | B41: 4800 | C41: 1992 | E41: Electronics | F41: 9500
A42: Webcam HD | B42: 800 | C42: 2500 | E42: Furniture | F42: 1300
...

Sheet Dashbord
E3: Digital Mart Pro
